Workbook

Sheet Sheet3
A1: Q2 Status | B1: All
A2: HP | B2: All
A3: Q1 Status | B3: All
A4: Q3 Status | B4: All
A5: Q4 Status | B5: (Multiple Items)
A7: Count of Section Name | B7: Column Labels
A8: Row Labels | B8: I | C8: II | D8: III | E8: IV | F8: IX | G8: KG I | H8: KG II | I8: Nursery | J8: Play Group | K8: V | L8: VI | M8: VII | N8: VIII | O8: X | P8: XI CAMBRIDGE | Q8: XI Com | R8: XI Hum | S8: XI Sci | T8: XII CAMBRIDGE | U8: XII Com | V8: XII Hum | W8: XII IBCP | X8: XII Sci | Y8: Grand Total
A9: A | B9: 11 | C9: 15 | D9: 11 | E9: 5 | F9: 4 | G9: 9 | H9: 12 | I9: 10 | J9: 9 | K9: 16 | L9: 9 | M9: 17 | N9: 7 | O9: 13 | S9: 39 | X9: 36 | Y9: 223
A10: B | B10: 11 | C10: 12 | D10: 13 | E10: 8 | F10: 12 | G10: 7 | H10: 9 | I10: 14 | J10: 11 | K10: 10 | L10: 11 | M10: 9 | N10: 9 | O10: 8 | S10: 62 | X10: 55 | Y10: 261
A11: C | B11: 5 | C11: 11 | D11: 5 | E11: 14 | F11: 12 | G11: 9 | H11: 9 | I11: 14 | K11: 11 | L11: 8 | M11: 10 | N11: 5 | O11: 15 | S11: 17 | X11: 23 | Y11: 168
A12: D | B12: 8 | C12: 12 | D12: 12 | E12: 9 | F12: 14 | G12: 6 | H12: 10 | K12: 10 | L12: 8 | M12: 11 | N12: 10 | O12: 14 | S12: 16 | X12: 17 | Y12: 157
A13: E | B13: 9 | C13: 9 | D13: 11 | E13: 5 | F13: 12 | G13: 8 | H13: 7 | K13: 13 | L13: 6 | M13: 11 | N13: 12 | O13: 9 | S13: 7 | X13: 13 | Y13: 132
A14: F | B14: 14 | C14: 13 | D14: 8 | E14: 10 | F14: 12 | G14: 7 | H14: 9 | K14: 17 | L14: 8 | M14: 15 | N14: 11 | O14: 10 | S14: 9 | X14: 24 | Y14: 167
A15: G | B15: 10 | C15: 7 | D15: 5 | E15: 5 | F15: 11 | G15: 7 | H15: 11 | K15: 14 | L15: 11 | M15: 8 | N15: 8 | O15: 15 | S15: 13 | X15: 13 | Y15: 138
A16: H | B16: 10 | C16: 5 | D16: 13 | E16: 11 | F16: 12 | H16: 9 | K16: 9 | L16: 11 | M16: 8 | N16: 7 | O16: 11 | S16: 26 | X16: 9 | Y16: 141
A17: I | B17: 11 | C17: 7 | D17: 12 | E17: 8 | F17: 11 | H17: 6 | K17: 11 | L17: 6 | M17: 13 | N17: 8 | O17: 14 | S17: 16 | X17: 7 | Y17: 130
A18: J | B18: 12 | C18: 5 | D18: 9 | E18: 7 | F18: 13 | K18: 11 | L18: 13 | M18: 11 | N18: 13 | O18: 13 | Q18: 7 | U18: 8 | Y18: 122
A19: K | B19: 10 | C19: 7 | D19: 9 | F19: 10 | L19: 14 | M19: 11 | N19: 12 | O19: 22 | Q19: 7 | U19: 10 | Y19: 112
A20: L | C20: 9 | Q20: 15 | U20: 10 | Y20: 34
A21: M | E21: 8 | F21: 3 | K21: 15 | L21: 7 | M21: 6 | N21: 9 | O21: 3 | Q21: 5 | U21: 3 | Y21: 59
A22: N | E22: 8 | Y22: 8
A23: O | R23: 15 | V23: 9 | Y23: 24
A24: Q | R24: 13 | V24: 5 | Y24: 18
A25: R | P25: 4 | T25: 2 | Y25: 6
A26: U | W26: 1 | Y26: 1
A27: Grand Total | B27: 111 | C27: 112 | D27: 108 | E27: 98 | F27: 126 | G27: 53 | H27: 82 | I27: 38 | J27: 20 | K27: 137 | L27: 112 | M27: 130 | N27: 111 | O27: 147 | P27: 4 | Q27: 34 | R27: 28 | S27: 205 | T27: 2 | U27: 31 | V27: 14 | W27: 1 | X27: 197 | Y27: 1901
T33: https://sirs.edu.in/admission/

Sheet Q3 Dashboard 
A1: Q2 Status | B1: (All)
A2: HP | B2: (All)
A3: Q1 Status | B3: (All)
A4: Q3 Status | B4: (Multiple Items)
A6: Count of Section Name | B6: Column Labels
A7: Row Labels | B7: I | C7: II | D7: III | E7: IV | F7: IX | G7: KG I | H7: KG II | I7: Nursery | J7: Play Group | K7: V | L7: VI | M7: VII | N7: VIII | O7: X | P7: XI CAMBRIDGE | Q7: XI Com | R7: XI Hum | S7: XI Sci | T7: XII CAMBRIDGE | U7: XII Com | V7: XII Hum | W7: XII Sci | X7: (blank) | Y7: XII IBCP | Z7: Grand Total
A8: A | B8: 24 | C8: 26 | D8: 26 | E8: 21 | F8: 19 | G8: 17 | H8: 20 | I8: 27 | J8: 20 | K8: 31 | L8: 26 | M8: 31 | N8: 29 | O8: 31 | S8: 67 | W8: 45 | Z8: 460
A9: B | B9: 21 | C9: 27 | D9: 24 | E9: 21 | F9: 25 | G9: 16 | H9: 19 | I9: 29 | J9: 19 | K9: 29 | L9: 26 | M9: 28 | N9: 28 | O9: 23 | S9: 93 | W9: 77 | Z9: 505
A10: C | B10: 22 | C10: 28 | D10: 15 | E10: 28 | F10: 31 | G10: 17 | H10: 18 | I10: 30 | K10: 30 | L10: 27 | M10: 31 | N10: 22 | O10: 31 | S10: 39 | W10: 45 | Z10: 414
A11: D | B11: 24 | C11: 23 | D11: 24 | E11: 27 | F11: 33 | G11: 15 | H11: 17 | K11: 28 | L11: 23 | M11: 26 | N11: 26 | O11: 30 | S11: 23 | W11: 39 | Z11: 358
A12: E | B12: 22 | C12: 21 | D12: 29 | E12: 21 | F12: 28 | G12: 16 | H12: 19 | K12: 27 | L12: 24 | M12: 30 | N12: 28 | O12: 32 | S12: 20 | W12: 25 | Z12: 342
A13: F | B13: 22 | C13: 22 | D13: 25 | E13: 22 | F13: 30 | G13: 17 | H13: 19 | K13: 28 | L13: 24 | M13: 28 | N13: 24 | O13: 28 | S13: 41 | W13: 40 | Z13: 370
A14: G | B14: 22 | C14: 22 | D14: 24 | E14: 22 | F14: 31 | G14: 15 | H14: 22 | K14: 24 | L14: 28 | M14: 27 | N14: 28 | O14: 35 | S14: 39 | W14: 34 | Z14: 373
A15: H | B15: 21 | C15: 19 | D15: 23 | E15: 24 | F15: 28 | H15: 18 | K15: 30 | L15: 24 | M15: 26 | N15: 25 | O15: 26 | S15: 59 | W15: 32 | Z15: 355
A16: I | B16: 22 | C16: 24 | D16: 22 | E16: 22 | F16: 33 | H16: 19 | K16: 30 | L16: 23 | M16: 29 | N16: 24 | O16: 31 | S16: 38 | W16: 34 | Z16: 351
A17: J | B17: 23 | C17: 12 | D17: 25 | E17: 21 | F17: 32 | K17: 27 | L17: 24 | M17: 27 | N17: 27 | O17: 26 | Q17: 28 | U17: 30 | Z17: 302
A18: K | B18: 15 | C18: 19 | D18: 25 | F18: 29 | L18: 28 | M18: 27 | N18: 26 | O18: 32 | Q18: 33 | U18: 30 | Z18: 264
A19: L | C19: 21 | Q19: 31 | U19: 33 | Z19: 85
A20: M | E20: 18 | F20: 13 | K20: 26 | L20: 19 | M20: 15 | N20: 22 | O20: 10 | Q20: 24 | U20: 24 | Z20: 171
A21: N | E21: 18 | Z21: 18
A22: O | R22: 34 | V22: 31 | Z22: 65
A23: Q | R23: 26 | V23: 24 | Z23: 50
A24: R | P24: 10 | T24: 5 | Z24: 15
A25: (blank)
A26: U | Y26: 3 | Z26: 3
A27: V | Y27: 3 | Z27: 3
A28: Grand Total | B28: 238 | C28: 264 | D28: 262 | E28: 265 | F28: 332 | G28: 113 | H28: 171 | I28: 86 | J28: 39 | K28: 310 | L28: 296 | M28: 325 | N28: 309 | O28: 335 | P28: 10 | Q28: 116 | R28: 60 | S28: 419 | T28: 5 | U28: 117 | V28: 55 | W28: 371 | Y28: 6 | Z28: 4504

Sheet Q1 Dashboard
A1: Q1 Status | B1: (Multiple Items)
A2: Admission Year | B2: (All)
A4: Count of Section Name | B4: Column Labels
A5: Row Labels | B5: I | C5: II | D5: III | E5: IV | F5: IX | G5: KG I | H5: KG II | I5: Nursery | J5: Play Group | K5: V | L5: VI | M5: VII | N5: VIII | O5: X | P5: XI Com | Q5: XI Hum | R5: XI Sci | S5: XII Com | T5: XII Hum | U5: XII Sci | V5: XII CAMBRIDGE | W5: XI CAMBRIDGE | X5: Grand Total
A6: A | B6: 24 | C6: 27 | D6: 29 | E6: 23 | F6: 21 | G6: 17 | H6: 20 | I6: 28 | J6: 20 | K6: 32 | L6: 26 | M6: 31 | N6: 29 | O6: 32 | R6: 68 | U6: 45 | X6: 472
A7: B | B7: 22 | C7: 27 | D7: 25 | E7: 22 | F7: 25 | G7: 16 | H7: 19 | I7: 29 | J7: 19 | K7: 30 | L7: 26 | M7: 28 | N7: 30 | O7: 25 | R7: 94 | U7: 77 | X7: 514
A8: C | B8: 22 | C8: 29 | D8: 16 | E8: 29 | F8: 30 | G8: 17 | H8: 18 | I8: 31 | K8: 30 | L8: 27 | M8: 32 | N8: 23 | O8: 31 | R8: 40 | U8: 46 | X8: 421
A9: D | B9: 24 | C9: 24 | D9: 24 | E9: 27 | F9: 34 | G9: 15 | H9: 18 | K9: 28 | L9: 25 | M9: 28 | N9: 26 | O9: 31 | R9: 26 | U9: 39 | X9: 369
A10: E | B10: 22 | C10: 22 | D10: 29 | E10: 21 | F10: 31 | G10: 16 | H10: 20 | K10: 29 | L10: 25 | M10: 30 | N10: 29 | O10: 33 | R10: 20 | U10: 25 | X10: 352
A11: F | B11: 22 | C11: 24 | D11: 26 | E11: 22 | F11: 30 | G11: 17 | H11: 19 | K11: 29 | L11: 24 | M11: 28 | N11: 25 | O11: 28 | R11: 41 | U11: 41 | X11: 376
A12: G | B12: 22 | C12: 24 | D12: 25 | E12: 23 | F12: 31 | G12: 17 | H12: 23 | K12: 26 | L12: 28 | M12: 28 | N12: 29 | O12: 35 | R12: 40 | U12: 34 | X12: 385
A13: H | B13: 22 | C13: 21 | D13: 23 | E13: 24 | F13: 29 | H13: 19 | K13: 30 | L13: 26 | M13: 26 | N13: 27 | O13: 28 | R13: 63 | U13: 35 | X13: 373
A14: I | B14: 22 | C14: 25 | D14: 22 | E14: 22 | F14: 33 | H14: 19 | K14: 30 | L14: 25 | M14: 29 | N14: 25 | O14: 32 | R14: 38 | U14: 34 | X14: 356
A15: J | B15: 23 | C15: 12 | D15: 25 | E15: 23 | F15: 32 | K15: 29 | L15: 25 | M15: 27 | N15: 28 | O15: 27 | P15: 29 | S15: 31 | X15: 311
A16: K | B16: 15 | C16: 20 | D16: 25 | F16: 31 | L16: 29 | M16: 28 | N16: 28 | O16: 32 | P16: 34 | S16: 33 | X16: 275
A17: L | C17: 21 | P17: 31 | S17: 33 | X17: 85
A18: M | E18: 18 | F18: 14 | K18: 27 | L18: 19 | M18: 15 | N18: 23 | O18: 11 | P18: 30 | S18: 29 | X18: 186
A19: N | E19: 18 | X19: 18
A20: O | Q20: 34 | T20: 33 | X20: 67
A21: Q | Q21: 27 | T21: 25 | X21: 52
A22: R | V22: 5 | W22: 11 | X22: 16
A23: Grand Total | B23: 240 | C23: 276 | D23: 269 | E23: 272 | F23: 341 | G23: 115 | H23: 175 | I23: 88 | J23: 39 | K23: 320 | L23: 305 | M23: 330 | N23: 322 | O23: 345 | P23: 124 | Q23: 61 | R23: 430 | S23: 126 | T23: 58 | U23: 376 | V23: 5 | W23: 11 | X23: 4628

Sheet Q2 Dashboard
A1: Q2 Status | B1: (Multiple Items)
A2: HP | B2: (All)
A3: Q1 Status | B3: (All)
A5: Count of Section Name | B5: Column Labels
A6: Row Labels | B6: I | C6: II | D6: III | E6: IV | F6: IX | G6: KG I | H6: KG II | I6: Nursery | J6: Play Group | K6: V | L6: VI | M6: VII | N6: VIII | O6: X | P6: XI CAMBRIDGE | Q6: XI Com | R6: XI Hum | S6: XI Sci | T6: XII CAMBRIDGE | U6: XII Com | V6: XII Hum | W6: XII Sci | X6: (blank) | Y6: XII IBCP | Z6: Grand Total
A7: A | B7: 24 | C7: 27 | D7: 27 | E7: 23 | F7: 21 | G7: 17 | H7: 20 | I7: 28 | J7: 20 | K7: 32 | L7: 26 | M7: 31 | N7: 29 | O7: 32 | S7: 68 | W7: 45 | Z7: 470
A8: B | B8: 22 | C8: 27 | D8: 25 | E8: 22 | F8: 25 | G8: 16 | H8: 19 | I8: 29 | J8: 19 | K8: 30 | L8: 26 | M8: 28 | N8: 30 | O8: 25 | S8: 94 | W8: 77 | Z8: 514
A9: C | B9: 22 | C9: 29 | D9: 16 | E9: 29 | F9: 30 | G9: 17 | H9: 18 | I9: 31 | K9: 30 | L9: 27 | M9: 32 | N9: 23 | O9: 31 | S9: 39 | W9: 46 | Z9: 420
A10: D | B10: 24 | C10: 24 | D10: 24 | E10: 27 | F10: 34 | G10: 15 | H10: 18 | K10: 28 | L10: 25 | M10: 28 | N10: 26 | O10: 31 | S10: 24 | W10: 39 | Z10: 367
A11: E | B11: 22 | C11: 22 | D11: 29 | E11: 21 | F11: 31 | G11: 16 | H11: 20 | K11: 29 | L11: 25 | M11: 30 | N11: 29 | O11: 33 | S11: 20 | W11: 25 | Z11: 352
A12: F | B12: 22 | C12: 24 | D12: 25 | E12: 22 | F12: 30 | G12: 17 | H12: 19 | K12: 29 | L12: 24 | M12: 28 | N12: 25 | O12: 28 | S12: 41 | W12: 41 | Z12: 375
A13: G | B13: 22 | C13: 23 | D13: 25 | E13: 23 | F13: 31 | G13: 17 | H13: 23 | K13: 26 | L13: 28 | M13: 28 | N13: 29 | O13: 35 | S13: 39 | W13: 34 | Z13: 383
A14: H | B14: 22 | C14: 21 | D14: 23 | E14: 24 | F14: 29 | H14: 19 | K14: 30 | L14: 26 | M14: 25 | N14: 26 | O14: 28 | S14: 63 | W14: 34 | Z14: 370
A15: I | B15: 22 | C15: 25 | D15: 22 | E15: 22 | F15: 33 | H15: 19 | K15: 30 | L15: 22 | M15: 29 | N15: 25 | O15: 32 | S15: 38 | W15: 34 | Z15: 353
A16: J | B16: 23 | C16: 12 | D16: 25 | E16: 23 | F16: 32 | K16: 29 | L16: 25 | M16: 27 | N16: 28 | O16: 27 | Q16: 29 | U16: 30 | Z16: 310
A17: K | B17: 15 | C17: 20 | D17: 25 | F17: 31 | L17: 29 | M17: 28 | N17: 28 | O17: 32 | Q17: 34 | U17: 33 | Z17: 275
A18: L | C18: 21 | Q18: 31 | U18: 33 | Z18: 85
A19: M | E19: 18 | F19: 14 | K19: 27 | L19: 19 | M19: 15 | N19: 23 | O19: 11 | Q19: 28 | U19: 27 | Z19: 182
A20: N | E20: 18 | Z20: 18
A21: O | R21: 34 | V21: 33 | Z21: 67
A22: Q | R22: 27 | V22: 24 | Z22: 51
A23: R | P23: 11 | T23: 5 | Z23: 16
A24: (blank)
A25: U | Y25: 3 | Z25: 3
A26: V | Y26: 3 | Z26: 3
A27: Grand Total | B27: 240 | C27: 275 | D27: 266 | E27: 272 | F27: 341 | G27: 115 | H27: 175 | I27: 88 | J27: 39 | K27: 320 | L27: 302 | M27: 329 | N27: 321 | O27: 345 | P27: 11 | Q27: 122 | R27: 61 | S27: 426 | T27: 5 | U27: 123 | V27: 57 | W27: 375 | Y27: 6 | Z27: 4614

Sheet Food Dashboard
A1: Food Status | B1: Yes
A3: Count of Admission No. | B3: Column Labels
A4: Row Labels | B4: I | C4: II | D4: III | E4: IV | F4: IX | G4: KG I | H4: KG II | I4: Nursery | J4: Play Group | K4: V | L4: VI | M4: VII | N4: VIII | O4: X | P4: XI CAMBRIDGE | Q4: XI Com | R4: XI Hum | S4: XI Sci | T4: XII CAMBRIDGE | U4: XII Com | V4: XII Hum | W4: XII Sci | X4: XII IBCP | Y4: Grand Total
A5: A | B5: 16 | C5: 20 | D5: 23 | E5: 17 | F5: 10 | G5: 14 | H5: 16 | I5: 12 | J5: 5 | K5: 26 | L5: 15 | M5: 18 | N5: 17 | O5: 22 | S5: 51 | W5: 26 | Y5: 308
A6: B | B6: 18 | C6: 23 | D6: 18 | E6: 16 | F6: 18 | G6: 13 | H6: 17 | I6: 17 | J6: 5 | K6: 20 | L6: 12 | M6: 16 | N6: 18 | O6: 14 | S6: 57 | W6: 43 | Y6: 325
A7: C | B7: 19 | C7: 21 | D7: 11 | E7: 25 | F7: 18 | G7: 17 | H7: 17 | I7: 14 | K7: 16 | L7: 14 | M7: 19 | N7: 19 | O7: 18 | S7: 17 | W7: 18 | Y7: 263
A8: D | B8: 19 | C8: 21 | D8: 18 | E8: 23 | F8: 17 | G8: 12 | H8: 16 | K8: 17 | L8: 12 | M8: 18 | N8: 12 | O8: 14 | S8: 18 | W8: 22 | Y8: 239
A9: E | B9: 15 | C9: 21 | D9: 22 | E9: 19 | F9: 17 | G9: 14 | H9: 16 | K9: 22 | L9: 9 | M9: 15 | N9: 18 | O9: 26 | S9: 10 | W9: 14 | Y9: 238
A10: F | B10: 16 | C10: 16 | D10: 19 | E10: 12 | F10: 19 | G10: 11 | H10: 17 | K10: 18 | L10: 6 | M10: 10 | N10: 15 | O10: 20 | S10: 19 | W10: 16 | Y10: 214
A11: G | B11: 19 | C11: 18 | D11: 21 | E11: 17 | F11: 20 | G11: 14 | H11: 18 | K11: 9 | L11: 7 | M11: 14 | N11: 18 | O11: 21 | S11: 17 | W11: 20 | Y11: 233
A12: H | B12: 20 | C12: 18 | D12: 18 | E12: 16 | F12: 21 | H12: 14 | K12: 19 | L12: 12 | M12: 18 | N12: 22 | O12: 17 | S12: 21 | W12: 19 | Y12: 235
A13: I | B13: 13 | C13: 18 | D13: 17 | E13: 16 | F13: 16 | H13: 16 | K13: 19 | L13: 12 | M13: 11 | N13: 13 | O13: 20 | S13: 13 | W13: 17 | Y13: 201
A14: J | B14: 15 | C14: 9 | D14: 18 | E14: 20 | F14: 20 | K14: 21 | L14: 13 | M14: 17 | N14: 17 | O14: 16 | Q14: 10 | U14: 13 | Y14: 189
A15: K | B15: 12 | C15: 16 | D15: 22 | F15: 18 | L15: 10 | M15: 16 | N15: 20 | O15: 19 | Q15: 15 | U15: 21 | Y15: 169
A16: L | C16: 16 | Q16: 18 | U16: 14 | Y16: 48
A17: M | E17: 12 | F17: 9 | K17: 18 | L17: 9 | M17: 2 | N17: 9 | O17: 7 | Q17: 12 | U17: 19 | Y17: 97
A18: N | E18: 17 | Y18: 17
A19: O | R19: 18 | V19: 18 | Y19: 36
A20: Q | R20: 13 | V20: 14 | Y20: 27
A21: R | P21: 7 | T21: 5 | Y21: 12
A22: U | X22: 2 | Y22: 2
A23: V | X23: 1 | Y23: 1
A24: Grand Total | B24: 182 | C24: 217 | D24: 207 | E24: 210 | F24: 203 | G24: 95 | H24: 147 | I24: 43 | J24: 10 | K24: 205 | L24: 131 | M24: 174 | N24: 198 | O24: 214 | P24: 7 | Q24: 55 | R24: 31 | S24: 223 | T24: 5 | U24: 67 | V24: 32 | W24: 195 | X24: 3 | Y24: 2854

Sheet Food
A1: Admission No. | B1: Food
A2: 15044 | B2: Yes
A3: 14917 | B3: Yes
A4: 15107 | B4: Yes
A5: 15101 | B5: Yes
A6: 15098 | B6: Yes
A7: 14648 | B7: Yes
A8: 15084 | B8: Yes
A9: 15069 | B9: Yes
A10: 15096 | B10: Yes
A11: 15095 | B11: Yes
A12: 6193 | B12: Yes
A13: 13590 | B13: Yes
... A2640: 14247 | B2640: Yes
A2641: A01810 | B2641: Yes
A2642: A01809 | B2642: Yes
A2643: A01807 | B2643: Yes
A2644: A01800 | B2644: Yes
A2645: A01769 | B2645: Yes
A2646: A01439 | B2646: Yes
A2647: A01657 | B2647: Yes
A2648: A01806 | B2648: Yes
A2649: A01796 | B2649: Yes
A2650: A01799 | B2650: Yes
A2651: A01798 | B2651: Yes
A2652: A01797 | B2652: Yes
... A2947: A01633 | B2947: Yes

Sheet Sheet4
A1: ADM
A2: 13928
A3: 14177
A4: 13943
A5: 2203
A6: 13968
A7: 13476
A8: 2292
A9: 13470
A10: 1012
A11: 13494
A12: 13456
A13: 13478
... A31: 13584

Sheet Sheet1

Sheet Student List
A1: Sr No. | B1: Admission No. | C1: Class Name | D1: Section Name | E1: Student Name | F1: Father Name | G1: Father Email Id | H1: Father Primary Contact | I1: Mother Name | J1: Mother Email Id | K1: Mother Primary Contact | L1: Admission Year | M1: HP | N1: Communication Remarks | O1: Oversight SMS | P1: Q1 Amount | Q1: Q1 Status | R1: Q2 Amount | S1: Q2 Status | T1: Q3 Amount | U1: Q3 Status | V1: Q4 Amount | W1: Q4 Status | X1: Food Status | Y1: Calling List | Z1: SMS Practical
A2: 1 | B2: A01819 | C2: Play Group | D2: A | E2: Aarav Patnaik | F2: Roshan Pattnaik | G2: roshan.pattnaik9@gmail.com | H2: 9861438648 | I2: Suryasikha Samal | J2: suryasikhasamal@gmail.com | K2: 9437627732 | L2: 2025-2026 | M2: =VLOOKUP(B2,'HP List'!A:G,7,0) -> #N/A | N2: =VLOOKUP(B2,'HP List'!A:H,8,0) -> #N/A | P2: =VLOOKUP(B2,'Q1'!A:B,2,0) -> #N/A | Q2: =IF(P2>5000,"Unpaid","Paid") -> #N/A | R2: =VLOOKUP(B2,'Q2'!A:B,2,0) -> #N/A | S2: =IF(R2>5000,"Unpaid","Paid") -> #N/A | T2: =VLOOKUP(B2,'Q3'!A:B,2,0) -> #N/A | U2: =IF(T2>5000,"Unpaid","Paid") -> #N/A | V2: =VLOOKUP(B2,'Q4'!A:B,2,0) -> #N/A | W2: =IF(V2>5000,"Unpaid","Paid") -> #N/A | X2: =VLOOKUP(B2,Food!A:B,2,0) -> #N/A | Y2: =VLOOKUP(B2,'Call List'!A:A,1,0) -> A01819 | Z2: =VLOOKUP(B2,Sheet4!A:A,1,0) -> #N/A
A3: 2 | B3: A01731 | C3: Play Group | D3: A | E3: Abhim Saikrishna Patra | F3: Ashok kumar Patra | G3: bandita.rout@gmail.com | H3: 9611555560 | I3: Bandita Rout | J3: bandita.rout@gmail.com | K3: 9916141694 | L3: 2025-2026 | M3: =VLOOKUP(B3,'HP List'!A:G,7,0) -> #N/A | N3: =VLOOKUP(B3,'HP List'!A:H,8,0) -> #N/A | P3: =VLOOKUP(B3,'Q1'!A:B,2,0) -> #N/A | Q3: =IF(P3>5000,"Unpaid","Paid") -> #N/A | R3: =VLOOKUP(B3,'Q2'!A:B,2,0) -> #N/A | S3: =IF(R3>5000,"Unpaid","Paid") -> #N/A | T3: =VLOOKUP(B3,'Q3'!A:B,2,0) -> #N/A | U3: =IF(T3>5000,"Unpaid","Paid") -> #N/A | V3: =VLOOKUP(B3,'Q4'!A:B,2,0) -> #N/A | W3: =IF(V3>5000,"Unpaid","Paid") -> #N/A | X3: =VLOOKUP(B3,Food!A:B,2,0) -> #N/A | Y3: =VLOOKUP(B3,'Call List'!A:A,1,0) -> A01731 | Z3: =VLOOKUP(B3,Sheet4!A:A,1,0) -> #N/A
A4: 3 | B4: A01798 | C4: Play Group | D4: A | E4: ADWAIT JENA | F4: NILADRI BHUSAN JENA | G4: nil354@gmail.com | H4: 9741288822 | I4: DEVISHREE DAS | J4: devishreedas111@gmail.com | K4: 8895299296 | L4: 2025-2026 | M4: =VLOOKUP(B4,'HP List'!A:G,7,0) -> #N/A | N4: =VLOOKUP(B4,'HP List'!A:H,8,0) -> #N/A | P4: =VLOOKUP(B4,'Q1'!A:B,2,0) -> #N/A | Q4: =IF(P4>5000,"Unpaid","Paid") -> #N/A | R4: =VLOOKUP(B4,'Q2'!A:B,2,0) -> #N/A | S4: =IF(R4>5000,"Unpaid","Paid") -> #N/A | T4: =VLOOKUP(B4,'Q3'!A:B,2,0) -> #N/A | U4: =IF(T4>5000,"Unpaid","Paid") -> #N/A | V4: =VLOOKUP(B4,'Q4'!A:B,2,0) -> 19950 | W4: =IF(V4>5000,"Unpaid","Paid") -> Unpaid | X4: =VLOOKUP(B4,Food!A:B,2,0) -> Yes | Y4: =VLOOKUP(B4,'Call List'!A:A,1,0) -> A01798 | Z4: =VLOOKUP(B4,Sheet4!A:A,1,0) -> #N/A
A5: 4 | B5: A01733 | C5: Play Group | D5: A | E5: Atharv Kumar Jena | F5: Ashis Kumar Jena | G5: subhashreepatra111@gmail.com | H5: 9668569257 | I5: Subhashree Patra | J5: subhashreepatra111@gmail.com | K5: 7504818550 | L5: 2025-2026 | M5: =VLOOKUP(B5,'HP List'!A:G,7,0) -> #N/A | N5: =VLOOKUP(B5,'HP List'!A:H,8,0) -> #N/A | P5: =VLOOKUP(B5,'Q1'!A:B,2,0) -> #N/A | Q5: =IF(P5>5000,"Unpaid","Paid") -> #N/A | R5: =VLOOKUP(B5,'Q2'!A:B,2,0) -> #N/A | S5: =IF(R5>5000,"Unpaid","Paid") -> #N/A | T5: =VLOOKUP(B5,'Q3'!A:B,2,0) -> #N/A | U5: =IF(T5>5000,"Unpaid","Paid") -> #N/A | V5: =VLOOKUP(B5,'Q4'!A:B,2,0) -> #N/A | W5: =IF(V5>5000,"Unpaid","Paid") -> #N/A | X5: =VLOOKUP(B5,Food!A:B,2,0) -> #N/A | Y5: =VLOOKUP(B5,'Call List'!A:A,1,0) -> A01733 | Z5: =VLOOKUP(B5,Sheet4!A:A,1,0) -> #N/A
A6: 5 | B6: A01836 | C6: Play Group | D6: A | E6: Avnesh Sahu | F6: Bijay Kumar Sahu | G6: drvjkumar19@gmail.com | H6: 7978672990 | I6: Aparna Sahu | J6: aparna.sahu90@gmail.com | K6: 7978672990 | L6: 2025-2026 | M6: =VLOOKUP(B6,'HP List'!A:G,7,0) -> #N/A | N6: =VLOOKUP(B6,'HP List'!A:H,8,0) -> #N/A | P6: =VLOOKUP(B6,'Q1'!A:B,2,0) -> #N/A | Q6: =IF(P6>5000,"Unpaid","Paid") -> #N/A | R6: =VLOOKUP(B6,'Q2'!A:B,2,0) -> #N/A | S6: =IF(R6>5000,"Unpaid","Paid") -> #N/A | T6: =VLOOKUP(B6,'Q3'!A:B,2,0) -> #N/A | U6: =IF(T6>5000,"Unpaid","Paid") -> #N/A | V6: =VLOOKUP(B6,'Q4'!A:B,2,0) -> 17550 | W6: =IF(V6>5000,"Unpaid","Paid") -> Unpaid | X6: =VLOOKUP(B6,Food!A:B,2,0) -> #N/A | Y6: =VLOOKUP(B6,'Call List'!A:A,1,0) -> #N/A | Z6: =VLOOKUP(B6,Sheet4!A:A,1,0) -> #N/A
A7: 6 | B7: A01828 | C7: Play Group | D7: A | E7: Bhavya Baibhabi Samal | F7: Himansu Kumar Samal | G7: himansu.ksamal@gmail.com | H7: 7328094532 | I7: Sarojini Swain | J7: swainsarojini84@gmail.com | K7: 9938594220 | L7: 2025-2026 | M7: =VLOOKUP(B7,'HP List'!A:G,7,0) -> #N/A | N7: =VLOOKUP(B7,'HP List'!A:H,8,0) -> #N/A | P7: =VLOOKUP(B7,'Q1'!A:B,2,0) -> #N/A | Q7: =IF(P7>5000,"Unpaid","Paid") -> #N/A | R7: =VLOOKUP(B7,'Q2'!A:B,2,0) -> #N/A | S7: =IF(R7>5000,"Unpaid","Paid") -> #N/A | T7: =VLOOKUP(B7,'Q3'!A:B,2,0) -> #N/A | U7: =IF(T7>5000,"Unpaid","Paid") -> #N/A | V7: =VLOOKUP(B7,'Q4'!A:B,2,0) -> 17550 | W7: =IF(V7>5000,"Unpaid","Paid") -> Unpaid | X7: =VLOOKUP(B7,Food!A:B,2,0) -> #N/A | Y7: =VLOOKUP(B7,'Call List'!A:A,1,0) -> A01828 | Z7: =VLOOKUP(B7,Sheet4!A:A,1,0) -> #N/A
A8: 7 | B8: A01692 | C8: Play Group | D8: A | E8: Devanshi Ashooja | F8: Subash Chandra Sahoo | G8: rpoojalin12@gmail.com | H8: 7008996806 | I8: Poojalin Rout | J8: subashsahoo1987@gmail.com | K8: 9040800262 | L8: 2025-2026 | M8: =VLOOKUP(B8,'HP List'!A:G,7,0) -> #N/A | N8: =VLOOKUP(B8,'HP List'!A:H,8,0) -> #N/A | P8: =VLOOKUP(B8,'Q1'!A:B,2,0) -> #N/A | Q8: =IF(P8>5000,"Unpaid","Paid") -> #N/A | R8: =VLOOKUP(B8,'Q2'!A:B,2,0) -> #N/A | S8: =IF(R8>5000,"Unpaid","Paid") -> #N/A | T8: =VLOOKUP(B8,'Q3'!A:B,2,0) -> #N/A | U8: =IF(T8>5000,"Unpaid","Paid") -> #N/A | V8: =VLOOKUP(B8,'Q4'!A:B,2,0) -> 17550 | W8: =IF(V8>5000,"Unpaid","Paid") -> Unpaid | X8: =VLOOKUP(B8,Food!A:B,2,0) -> #N/A | Y8: =VLOOKUP(B8,'Call List'!A:A,1,0) -> A01692 | Z8: =VLOOKUP(B8,Sheet4!A:A,1,0) -> #N/A
A9: 8 | B9: A01757 | C9: Play Group | D9: A | E9: Ishanvi Ray | F9: Satyabrata Barik | G9: barik.satyabratta@gmail.com | H9: 9078245246 | I9: Sweta Priyadarshinee | J9: swetapriyadarshinee@gmail.com | K9: 8658518351 | L9: 2025-2026 | M9: =VLOOKUP(B9,'HP List'!A:G,7,0) -> #N/A | N9: =VLOOKUP(B9,'HP List'!A:H,8,0) -> #N/A | P9: =VLOOKUP(B9,'Q1'!A:B,2,0) -> #N/A | Q9: =IF(P9>5000,"Unpaid","Paid") -> #N/A | R9: =VLOOKUP(B9,'Q2'!A:B,2,0) -> #N/A | S9: =IF(R9>5000,"Unpaid","Paid") -> #N/A | T9: =VLOOKUP(B9,'Q3'!A:B,2,0) -> #N/A | U9: =IF(T9>5000,"Unpaid","Paid") -> #N/A | V9: =VLOOKUP(B9,'Q4'!A:B,2,0) -> #N/A | W9: =IF(V9>5000,"Unpaid","Paid") -> #N/A | X9: =VLOOKUP(B9,Food!A:B,2,0) -> #N/A | Y9: =VLOOKUP(B9,'Call List'!A:A,1,0) -> A01757 | Z9: =VLOOKUP(B9,Sheet4!A:A,1,0) -> #N/A
A10: 9 | B10: A01790 | C10: Play Group | D10: A | E10: Jivisha Pasayat | F10: Parth Pratim Pasayat | G10: parth_p3@live.com | H10: 9643334119 | I10: Swati Pradhan | J10: swatipradhan91@gmail.com | K10: 8018161589 | L10: 2025-2026 | M10: =VLOOKUP(B10,'HP List'!A:G,7,0) -> #N/A | N10: =VLOOKUP(B10,'HP List'!A:H,8,0) -> #N/A | P10: =VLOOKUP(B10,'Q1'!A:B,2,0) -> #N/A | Q10: =IF(P10>5000,"Unpaid","Paid") -> #N/A | R10: =VLOOKUP(B10,'Q2'!A:B,2,0) -> #N/A | S10: =IF(R10>5000,"Unpaid","Paid") -> #N/A | T10: =VLOOKUP(B10,'Q3'!A:B,2,0) -> #N/A | U10: =IF(T10>5000,"Unpaid","Paid") -> #N/A | V10: =VLOOKUP(B10,'Q4'!A:B,2,0) -> #N/A | W10: =IF(V10>5000,"Unpaid","Paid") -> #N/A | X10: =VLOOKUP(B10,Food!A:B,2,0) -> #N/A | Y10: =VLOOKUP(B10,'Call List'!A:A,1,0) -> A01790 | Z10: =VLOOKUP(B10,Sheet4!A:A,1,0) -> #N/A
A11: 10 | B11: A01771 | C11: Play Group | D11: A | E11: Krishnapriya Panda | F11: Rashmi Ranjan Panda | G11: lipuni.mitali@gmail.com | H11: 6372214177 | I11: Mitali Mohapatra | J11: lipuni.mitali@gmail.com | K11: 6372214177 | L11: 2025-2026 | M11: =VLOOKUP(B11,'HP List'!A:G,7,0) -> #N/A | N11: =VLOOKUP(B11,'HP List'!A:H,8,0) -> #N/A | P11: =VLOOKUP(B11,'Q1'!A:B,2,0) -> #N/A | Q11: =IF(P11>5000,"Unpaid","Paid") -> #N/A | R11: =VLOOKUP(B11,'Q2'!A:B,2,0) -> #N/A | S11: =IF(R11>5000,"Unpaid","Paid") -> #N/A | T11: =VLOOKUP(B11,'Q3'!A:B,2,0) -> #N/A | U11: =IF(T11>5000,"Unpaid","Paid") -> #N/A | V11: =VLOOKUP(B11,'Q4'!A:B,2,0) -> 17550 | W11: =IF(V11>5000,"Unpaid","Paid") -> Unpaid | X11: =VLOOKUP(B11,Food!A:B,2,0) -> #N/A | Y11: =VLOOKUP(B11,'Call List'!A:A,1,0) -> A01771 | Z11: =VLOOKUP(B11,Sheet4!A:A,1,0) -> #N/A
A12: 11 | B12: A01827 | C12: Play Group | D12: A | E12: Nirvaan Swain | F12: Sandeep Swain | G12: sandeep.swainrkl@gmail.com | H12: 9945053805 | I12: Prerana Jena | J12: prerna187@gmail.com | K12: 9686565486 | L12: 2025-2026 | M12: =VLOOKUP(B12,'HP List'!A:G,7,0) -> #N/A | N12: =VLOOKUP(B12,'HP List'!A:H,8,0) -> #N/A | P12: =VLOOKUP(B12,'Q1'!A:B,2,0) -> #N/A | Q12: =IF(P12>5000,"Unpaid","Paid") -> #N/A | R12: =VLOOKUP(B12,'Q2'!A:B,2,0) -> #N/A | S12: =IF(R12>5000,"Unpaid","Paid") -> #N/A | T12: =VLOOKUP(B12,'Q3'!A:B,2,0) -> #N/A | U12: =IF(T12>5000,"Unpaid","Paid") -> #N/A | V12: =VLOOKUP(B12,'Q4'!A:B,2,0) -> 17550 | W12: =IF(V12>5000,"Unpaid","Paid") -> Unpaid | X12: =VLOOKUP(B12,Food!A:B,2,0) -> #N/A | Y12: =VLOOKUP(B12,'Call List'!A:A,1,0) -> A01827 | Z12: =VLOOKUP(B12,Sheet4!A:A,1,0) -> #N/A
A13: 12 | B13: A01815 | C13: Play Group | D13: A | E13: Raj Reyansh Shukla | F13: Raj Rishabh Shukla | G13: raajrishabhshukla@gmail.com | H13: 9560273697 | I13: Deepshikha | J13: deepshikhalawer@gmail.com | K13: 9661085048 | L13: 2025-2026 | M13: =VLOOKUP(B13,'HP List'!A:G,7,0) -> #N/A | N13: =VLOOKUP(B13,'HP List'!A:H,8,0) -> #N/A | P13: =VLOOKUP(B13,'Q1'!A:B,2,0) -> #N/A | Q13: =IF(P13>5000,"Unpaid","Paid") -> #N/A | R13: =VLOOKUP(B13,'Q2'!A:B,2,0) -> #N/A | S13: =IF(R13>5000,"Unpaid","Paid") -> #N/A | T13: =VLOOKUP(B13,'Q3'!A:B,2,0) -> #N/A | U13: =IF(T13>5000,"Unpaid","Paid") -> #N/A | V13: =VLOOKUP(B13,'Q4'!A:B,2,0) -> #N/A | W13: =IF(V13>5000,"Unpaid","Paid") -> #N/A | X13: =VLOOKUP(B13,Food!A:B,2,0) -> #N/A | Y13: =VLOOKUP(B13,'Call List'!A:A,1,0) -> A01815 | Z13: =VLOOKUP(B13,Sheet4!A:A,1,0) -> #N/A
... A106: 105 | B106: A01721 | C106: Nursery | D106: C | E106: B Sharvil Shivansh | F106: Manabhanjan Behera | G106: maafs183868@gmail.com | H106: 9937202000 | I106: Madhusmita Swain | J106: madhusmitapuchi@gmail.com | K106: 7978124892 | L106: 2025-2026 | M106: =VLOOKUP(B106,'HP List'!A:G,7,0) -> #N/A | N106: =VLOOKUP(B106,'HP List'!A:H,8,0) -> #N/A | P106: =VLOOKUP(B106,'Q1'!A:B,2,0) -> #N/A | Q106: =IF(P106>5000,"Unpaid","Paid") -> #N/A | R106: =VLOOKUP(B106,'Q2'!A:B,2,0) -> #N/A | S106: =IF(R106>5000,"Unpaid","Paid") -> #N/A | T106: =VLOOKUP(B106,'Q3'!A:B,2,0) -> #N/A | U106: =IF(T106>5000,"Unpaid","Paid") -> #N/A | V106: =VLOOKUP(B106,'Q4'!A:B,2,0) -> 36015 | W106: =IF(V106>5000,"Unpaid","Paid") -> Unpaid | X106: =VLOOKUP(B106,Food!A:B,2,0) -> Yes | Y106: =VLOOKUP(B106,'Call List'!A:A,1,0) -> A01721 | Z106: =VLOOKUP(B106,Sheet4!A:A,1,0) -> #N/A
A107: 106 | B107: A01476 | C107: Nursery | D107: C | E107: Dakshya Nandini Dalai | F107: Umasankar Dalai | G107: umasankardalai1981@gmail.com | H107: 9438465846 | I107: Sunita Dalai | J107: sunitadalai3007@gmail.com | K107: 9439925911 | L107: 2024-2025 | M107: =VLOOKUP(B107,'HP List'!A:G,7,0) -> #N/A | N107: =VLOOKUP(B107,'HP List'!A:H,8,0) -> #N/A | P107: =VLOOKUP(B107,'Q1'!A:B,2,0) -> #N/A | Q107: =IF(P107>5000,"Unpaid","Paid") -> #N/A | R107: =VLOOKUP(B107,'Q2'!A:B,2,0) -> #N/A | S107: =IF(R107>5000,"Unpaid","Paid") -> #N/A | T107: =VLOOKUP(B107,'Q3'!A:B,2,0) -> #N/A | U107: =IF(T107>5000,"Unpaid","Paid") -> #N/A | V107: =VLOOKUP(B107,'Q4'!A:B,2,0) -> #N/A | W107: =IF(V107>5000,"Unpaid","Paid") -> #N/A | X107: =VLOOKUP(B107,Food!A:B,2,0) -> #N/A | Y107: =VLOOKUP(B107,'Call List'!A:A,1,0) -> A01476 | Z107: =VLOOKUP(B107,Sheet4!A:A,1,0) -> #N/A | AA107: SRP
A108: 107 | B108: A01598 | C108: Nursery | D108: C | E108: Dhruva Kumar Patra | F108: Dillip Kumar Patra | G108: patradillip91@gmail.com | H108: 7978681617 | I108: Sashikala Biswal | J108: b.arushi1993@gmail.com | K108: 6372848323 | L108: 2024-2025 | M108: =VLOOKUP(B108,'HP List'!A:G,7,0) -> #N/A | N108: =VLOOKUP(B108,'HP List'!A:H,8,0) -> #N/A | P108: =VLOOKUP(B108,'Q1'!A:B,2,0) -> #N/A | Q108: =IF(P108>5000,"Unpaid","Paid") -> #N/A | R108: =VLOOKUP(B108,'Q2'!A:B,2,0) -> #N/A | S108: =IF(R108>5000,"Unpaid","Paid") -> #N/A | T108: =VLOOKUP(B108,'Q3'!A:B,2,0) -> #N/A | U108: =IF(T108>5000,"Unpaid","Paid") -> #N/A | V108: =VLOOKUP(B108,'Q4'!A:B,2,0) -> 29715 | W108: =IF(V108>5000,"Unpaid","Paid") -> Unpaid | X108: =VLOOKUP(B108,Food!A:B,2,0) -> #N/A | Y108: =VLOOKUP(B108,'Call List'!A:A,1,0) -> A01598 | Z108: =VLOOKUP(B108,Sheet4!A:A,1,0) -> #N/A
A109: 108 | B109: A01457 | C109: Nursery | D109: C | E109: Krishiv Dey | F109: Abinash Kumar Dey | G109: abinashkudey@gmail.com | H109: 9438062303 | I109: Susmita Sen | J109: susmita98payal@gmail.com | K109: 9777662277 | L109: 2024-2025 | M109: =VLOOKUP(B109,'HP List'!A:G,7,0) -> #N/A | N109: =VLOOKUP(B109,'HP List'!A:H,8,0) -> #N/A | P109: =VLOOKUP(B109,'Q1'!A:B,2,0) -> #N/A | Q109: =IF(P109>5000,"Unpaid","Paid") -> #N/A | R109: =VLOOKUP(B109,'Q2'!A:B,2,0) -> #N/A | S109: =IF(R109>5000,"Unpaid","Paid") -> #N/A | T109: =VLOOKUP(B109,'Q3'!A:B,2,0) -> #N/A | U109: =IF(T109>5000,"Unpaid","Paid") -> #N/A | V109: =VLOOKUP(B109,'Q4'!A:B,2,0) -> #N/A | W109: =IF(V109>5000,"Unpaid","Paid") -> #N/A | X109: =VLOOKUP(B109,Food!A:B,2,0) -> #N/A | Y109: =VLOOKUP(B109,'Call List'!A:A,1,0) -> A01457 | Z109: =VLOOKUP(B109,Sheet4!A:A,1,0) -> #N/A
A110: 109 | B110: A01751 | C110: Nursery | D110: C | E110: Kritika Mohapatra | F110: Patitapaban Mohapatra | G110: ritarani1991@gmail.com | H110: 9937357251 | I110: Ritarani Mohapatra | J110: ritarani1991@gmail.com | K110: 8763550833 | L110: 2025-2026 | M110: =VLOOKUP(B110,'HP List'!A:G,7,0) -> #N/A | N110: =VLOOKUP(B110,'HP List'!A:H,8,0) -> #N/A | P110: =VLOOKUP(B110,'Q1'!A:B,2,0) -> #N/A | Q110: =IF(P110>5000,"Unpaid","Paid") -> #N/A | R110: =VLOOKUP(B110,'Q2'!A:B,2,0) -> #N/A | S110: =IF(R110>5000,"Unpaid","Paid") -> #N/A | T110: =VLOOKUP(B110,'Q3'!A:B,2,0) -> #N/A | U110: =IF(T110>5000,"Unpaid","Paid") -> #N/A | V110: =VLOOKUP(B110,'Q4'!A:B,2,0) -> #N/A | W110: =IF(V110>5000,"Unpaid","Paid") -> #N/A | X110: =VLOOKUP(B110,Food!A:B,2,0) -> #N/A | Y110: =VLOOKUP(B110,'Call List'!A:A,1,0) -> A01751 | Z110: =VLOOKUP(B110,Sheet4!A:A,1,0) -> #N/A
A111: 110 | B111: A01656 | C111: Nursery | D111: C | E111: Kuldeep Paikaray | F111: Soubhagya Ranjan Paikaray | G111: soubhagyapaikaray15@gmail.com | H111: 7008959467 | I111: Subhashree Mohanty | J111: subhashreesrp@gmail.com | K111: 7978484438 | L111: 2025-2026 | M111: =VLOOKUP(B111,'HP List'!A:G,7,0) -> #N/A | N111: =VLOOKUP(B111,'HP List'!A:H,8,0) -> #N/A | P111: =VLOOKUP(B111,'Q1'!A:B,2,0) -> #N/A | Q111: =IF(P111>5000,"Unpaid","Paid") -> #N/A | R111: =VLOOKUP(B111,'Q2'!A:B,2,0) -> #N/A | S111: =IF(R111>5000,"Unpaid","Paid") -> #N/A | T111: =VLOOKUP(B111,'Q3'!A:B,2,0) -> #N/A | U111: =IF(T111>5000,"Unpaid","Paid") -> #N/A | V111: =VLOOKUP(B111,'Q4'!A:B,2,0) -> 45615 | W111: =IF(V111>5000,"Unpaid","Paid") -> Unpaid | X111: =VLOOKUP(B111,Food!A:B,2,0) -> #N/A | Y111: =VLOOKUP(B111,'Call List'!A:A,1,0) -> A01656 | Z111: =VLOOKUP(B111,Sheet4!A:A,1,0) -> #N/A
A112: 111 | B112: A01540 | C112: Nursery | D112: C | E112: Mohammad Rayyan Humaid | F112: Mohammad Mohtesam | G112: mohd.mohtesam@gmail.com | H112: 7092807894 | I112: Nazma Ali | J112: nazmaali2010@gmail.com | K112: 8237305136 | L112: 2024-2025 | M112: =VLOOKUP(B112,'HP List'!A:G,7,0) -> #N/A | N112: =VLOOKUP(B112,'HP List'!A:H,8,0) -> #N/A | P112: =VLOOKUP(B112,'Q1'!A:B,2,0) -> #N/A | Q112: =IF(P112>5000,"Unpaid","Paid") -> #N/A | R112: =VLOOKUP(B112,'Q2'!A:B,2,0) -> #N/A | S112: =IF(R112>5000,"Unpaid","Paid") -> #N/A | T112: =VLOOKUP(B112,'Q3'!A:B,2,0) -> #N/A | U112: =IF(T112>5000,"Unpaid","Paid") -> #N/A | V112: =VLOOKUP(B112,'Q4'!A:B,2,0) -> #N/A | W112: =IF(V112>5000,"Unpaid","Paid") -> #N/A | X112: =VLOOKUP(B112,Food!A:B,2,0) -> #N/A | Y112: =VLOOKUP(B112,'Call List'!A:A,1,0) -> A01540 | Z112: =VLOOKUP(B112,Sheet4!A:A,1,0) -> #N/A
A113: 112 | B113: A01763 | C113: Nursery | D113: C | E113: Nehanshi Sahoo | F113: Suresh Kumar Sahoo | G113: suresh.ksahoo@yahoo.com | H113: 9324835868 | I113: Priyanka Priyadarshani | J113: suresh.ksahoo@yahoo.com | K113: 7008627037 | L113: 2025-2026 | M113: =VLOOKUP(B113,'HP List'!A:G,7,0) -> #N/A | N113: =VLOOKUP(B113,'HP List'!A:H,8,0) -> #N/A | P113: =VLOOKUP(B113,'Q1'!A:B,2,0) -> #N/A | Q113: =IF(P113>5000,"Unpaid","Paid") -> #N/A | R113: =VLOOKUP(B113,'Q2'!A:B,2,0) -> #N/A | S113: =IF(R113>5000,"Unpaid","Paid") -> #N/A | T113: =VLOOKUP(B113,'Q3'!A:B,2,0) -> #N/A | U113: =IF(T113>5000,"Unpaid","Paid") -> #N/A | V113: =VLOOKUP(B113,'Q4'!A:B,2,0) -> #N/A | W113: =IF(V113>5000,"Unpaid","Paid") -> #N/A | X113: =VLOOKUP(B113,Food!A:B,2,0) -> Yes | Y113: =VLOOKUP(B113,'Call List'!A:A,1,0) -> A01763 | Z113: =VLOOKUP(B113,Sheet4!A:A,1,0) -> #N/A
A114: 113 | B114: A01789 | C114: Nursery | D114: C | E114: NS Adwait Dhal | F114: Nishikanta Dhal | G114: dhalbapu1588@gmail.com | H114: 9681330762 | I114: Sasmita Routray | J114: dhalbapu1588@gmail.com | K114: 7019975848 | L114: 2025-2026 | M114: =VLOOKUP(B114,'HP List'!A:G,7,0) -> #N/A | N114: =VLOOKUP(B114,'HP List'!A:H,8,0) -> #N/A | P114: =VLOOKUP(B114,'Q1'!A:B,2,0) -> #N/A | Q114: =IF(P114>5000,"Unpaid","Paid") -> #N/A | R114: =VLOOKUP(B114,'Q2'!A:B,2,0) -> #N/A | S114: =IF(R114>5000,"Unpaid","Paid") -> #N/A | T114: =VLOOKUP(B114,'Q3'!A:B,2,0) -> #N/A | U114: =IF(T114>5000,"Unpaid","Paid") -> #N/A | V114: =VLOOKUP(B114,'Q4'!A:B,2,0) -> 29715 | W114: =IF(V114>5000,"Unpaid","Paid") -> Unpaid | X114: =VLOOKUP(B114,Food!A:B,2,0) -> #N/A | Y114: =VLOOKUP(B114,'Call List'!A:A,1,0) -> A01789 | Z114: =VLOOKUP(B114,Sheet4!A:A,1,0) -> #N/A
A115: 114 | B115: A01814 | C115: Nursery | D115: C | E115: Praneet Raut | F115: Pramod Raut | G115: bapijenabapi883@gmail.com | H115: 8342840377 | I115: Priyanka Jena | J115: bapijenabapi883@gmail.com | K115: 7377987880 | L115: 2025-2026 | M115: =VLOOKUP(B115,'HP List'!A:G,7,0) -> #N/A | N115: =VLOOKUP(B115,'HP List'!A:H,8,0) -> #N/A | P115: =VLOOKUP(B115,'Q1'!A:B,2,0) -> #N/A | Q115: =IF(P115>5000,"Unpaid","Paid") -> #N/A | R115: =VLOOKUP(B115,'Q2'!A:B,2,0) -> #N/A | S115: =IF(R115>5000,"Unpaid","Paid") -> #N/A | T115: =VLOOKUP(B115,'Q3'!A:B,2,0) -> 45878 | U115: =IF(T115>5000,"Unpaid","Paid") -> Unpaid | V115: =VLOOKUP(B115,'Q4'!A:B,2,0) -> 87757 | W115: =IF(V115>5000,"Unpaid","Paid") -> Unpaid | X115: =VLOOKUP(B115,Food!A:B,2,0) -> #N/A | Y115: =VLOOKUP(B115,'Call List'!A:A,1,0) -> A01814 | Z115: =VLOOKUP(B115,Sheet4!A:A,1,0) -> #N/A
A116: 115 | B116: A01432 | C116: Nursery | D116: C | E116: Prerit Sikaria | F116: Anish Sikaria | G116: sikaria_anish@yahoo.co.in | H116: 9234372371 | I116: Priyanka Agarwal | J116: priyanka.agrwl581@gmail.com | K116: 9937752179 | L116: 2024-2025 | M116: =VLOOKUP(B116,'HP List'!A:G,7,0) -> #N/A | N116: =VLOOKUP(B116,'HP List'!A:H,8,0) -> #N/A | P116: =VLOOKUP(B116,'Q1'!A:B,2,0) -> #N/A | Q116: =IF(P116>5000,"Unpaid","Paid") -> #N/A | R116: =VLOOKUP(B116,'Q2'!A:B,2,0) -> #N/A | S116: =IF(R116>5000,"Unpaid","Paid") -> #N/A | T116: =VLOOKUP(B116,'Q3'!A:B,2,0) -> #N/A | U116: =IF(T116>5000,"Unpaid","Paid") -> #N/A | V116: =VLOOKUP(B116,'Q4'!A:B,2,0) -> #N/A | W116: =IF(V116>5000,"Unpaid","Paid") -> #N/A | X116: =VLOOKUP(B116,Food!A:B,2,0) -> Yes | Y116: =VLOOKUP(B116,'Call List'!A:A,1,0) -> A01432 | Z116: =VLOOKUP(B116,Sheet4!A:A,1,0) -> #N/A
A117: 116 | B117: A01639 | C117: Nursery | D117: C | E117: Riddhi Siddharth | F117: Siddharth Ravi | G117: siddharth.rav@gmail.com | H117: 9945190016 | I117: Soumya Sasi | J117: niki.sasi8888@gmail.com | K117: 9692153131 | L117: 2024-2025 | M117: =VLOOKUP(B117,'HP List'!A:G,7,0) -> #N/A | N117: =VLOOKUP(B117,'HP List'!A:H,8,0) -> #N/A | P117: =VLOOKUP(B117,'Q1'!A:B,2,0) -> #N/A | Q117: =IF(P117>5000,"Unpaid","Paid") -> #N/A | R117: =VLOOKUP(B117,'Q2'!A:B,2,0) -> #N/A | S117: =IF(R117>5000,"Unpaid","Paid") -> #N/A | T117: =VLOOKUP(B117,'Q3'!A:B,2,0) -> #N/A | U117: =IF(T117>5000,"Unpaid","Paid") -> #N/A | V117: =VLOOKUP(B117,'Q4'!A:B,2,0) -> #N/A | W117: =IF(V117>5000,"Unpaid","Paid") -> #N/A | X117: =VLOOKUP(B117,Food!A:B,2,0) -> Yes | Y117: =VLOOKUP(B117,'Call List'!A:A,1,0) -> A01639 | Z117: =VLOOKUP(B117,Sheet4!A:A,1,0) -> #N/A
A118: 117 | B118: A01637 | C118: Nursery | D118: C | E118: Rishan Chakraborty | F118: Ramen Kumar Chakraborty | G118: romichkrbrt@gmail.com | H118: 8260500911 | I118: Manisha Sen | J118: senmanisha91@gmail.com | K118: 9051115041 | L118: 2025-2026 | M118: =VLOOKUP(B118,'HP List'!A:G,7,0) -> #N/A | N118: =VLOOKUP(B118,'HP List'!A:H,8,0) -> #N/A | P118: =VLOOKUP(B118,'Q1'!A:B,2,0) -> #N/A | Q118: =IF(P118>5000,"Unpaid","Paid") -> #N/A | R118: =VLOOKUP(B118,'Q2'!A:B,2,0) -> #N/A | S118: =IF(R118>5000,"Unpaid","Paid") -> #N/A | T118: =VLOOKUP(B118,'Q3'!A:B,2,0) -> #N/A | U118: =IF(T118>5000,"Unpaid","Paid") -> #N/A | V118: =VLOOKUP(B118,'Q4'!A:B,2,0) -> #N/A | W118: =IF(V118>5000,"Unpaid","Paid") -> #N/A | X118: =VLOOKUP(B118,Food!A:B,2,0) -> #N/A | Y118: =VLOOKUP(B118,'Call List'!A:A,1,0) -> A01637 | Z118: =VLOOKUP(B118,Sheet4!A:A,1,0) -> #N/A
A119: 118 | B119: A01802 | C119: Nursery | D119: C | E119: SATVIK ROUT | F119: SAUMYA RANJAN ROUT | G119: ssdrsony2@gmail.com | H119: 9853963652 | I119: SOUMYA SUCHARITA | J119: ssdrsony2@gmail.com | K119: 9861670922 | L119: 2025-2026 | M119: =VLOOKUP(B119,'HP List'!A:G,7,0) -> #N/A | N119: =VLOOKUP(B119,'HP List'!A:H,8,0) -> #N/A | P119: =VLOOKUP(B119,'Q1'!A:B,2,0) -> #N/A | Q119: =IF(P119>5000,"Unpaid","Paid") -> #N/A | R119: =VLOOKUP(B119,'Q2'!A:B,2,0) -> #N/A | S119: =IF(R119>5000,"Unpaid","Paid") -> #N/A | T119: =VLOOKUP(B119,'Q3'!A:B,2,0) -> #N/A | U119: =IF(T119>5000,"Unpaid","Paid") -> #N/A | V119: =VLOOKUP(B119,'Q4'!A:B,2,0) -> #N/A | W119: =IF(V119>5000,"Unpaid","Paid") -> #N/A | X119: =VLOOKUP(B119,Food!A:B,2,0) -> #N/A | Y119: =VLOOKUP(B119,'Call List'!A:A,1,0) -> A01802 | Z119: =VLOOKUP(B119,Sheet4!A:A,1,0) -> #N/A
... A279: 278 | B279: A01435 | C279: KG II | D279: B | E279: Reezy Rashmi Ray | F279: Rashmi Ranjan Rout | G279: rashmirout2012@gmail.com | H279: 9658276650 | I279: Rajanigandha Swain | J279: rashmirout2012@gmail.com | K279: 9658233319 | L279: 2024-2025 | M279: =VLOOKUP(B279,'HP List'!A:G,7,0) -> #N/A | N279: =VLOOKUP(B279,'HP List'!A:H,8,0) -> #N/A | P279: =VLOOKUP(B279,'Q1'!A:B,2,0) -> #N/A | Q279: =IF(P279>5000,"Unpaid","Paid") -> #N/A | R279: =VLOOKUP(B279,'Q2'!A:B,2,0) -> #N/A | S279: =IF(R279>5000,"Unpaid","Paid") -> #N/A | T279: =VLOOKUP(B279,'Q3'!A:B,2,0) -> #N/A | U279: =IF(T279>5000,"Unpaid","Paid") -> #N/A | V279: =VLOOKUP(B279,'Q4'!A:B,2,0) -> 40410 | W279: =IF(V279>5000,"Unpaid","Paid") -> Unpaid | X279: =VLOOKUP(B279,Food!A:B,2,0) -> Yes | Y279: =VLOOKUP(B279,'Call List'!A:A,1,0) -> A01435 | Z279: =VLOOKUP(B279,Sheet4!A:A,1,0) -> #N/A
A280: 279 | B280: A01677 | C280: KG II | D280: B | E280: Riyansh Raj | F280: Rashmi Ranjan Sahoo | H280: 9348365696 | I280: Sujata Pradhan | J280: sujats1992@gmail.com | K280: 9348365696 | L280: 2025-2026 | M280: =VLOOKUP(B280,'HP List'!A:G,7,0) -> #N/A | N280: =VLOOKUP(B280,'HP List'!A:H,8,0) -> #N/A | P280: =VLOOKUP(B280,'Q1'!A:B,2,0) -> #N/A | Q280: =IF(P280>5000,"Unpaid","Paid") -> #N/A | R280: =VLOOKUP(B280,'Q2'!A:B,2,0) -> #N/A | S280: =IF(R280>5000,"Unpaid","Paid") -> #N/A | T280: =VLOOKUP(B280,'Q3'!A:B,2,0) -> #N/A | U280: =IF(T280>5000,"Unpaid","Paid") -> #N/A | V280: =VLOOKUP(B280,'Q4'!A:B,2,0) -> 54060 | W280: =IF(V280>5000,"Unpaid","Paid") -> Unpaid | X280: =VLOOKUP(B280,Food!A:B,2,0) -> Yes | Y280: =VLOOKUP(B280,'Call List'!A:A,1,0) -> A01677 | Z280: =VLOOKUP(B280,Sheet4!A:A,1,0) -> #N/A
A281: 280 | B281: A01259 | C281: KG II | D281: B | E281: Shivansh Mohanayak | F281: Rupak kumar Mohanayak | G281: rmohanayak@gmail.com | H281: 9776838777 | I281: Ashapriya Sasmal | J281: rmohanayak@gmail.com | K281: 8763044710 | L281: 2022-2023 | M281: =VLOOKUP(B281,'HP List'!A:G,7,0) -> #N/A | N281: =VLOOKUP(B281,'HP List'!A:H,8,0) -> #N/A | P281: =VLOOKUP(B281,'Q1'!A:B,2,0) -> #N/A | Q281: =IF(P281>5000,"Unpaid","Paid") -> #N/A | R281: =VLOOKUP(B281,'Q2'!A:B,2,0) -> #N/A | S281: =IF(R281>5000,"Unpaid","Paid") -> #N/A | T281: =VLOOKUP(B281,'Q3'!A:B,2,0) -> #N/A | U281: =IF(T281>5000,"Unpaid","Paid") -> #N/A | V281: =VLOOKUP(B281,'Q4'!A:B,2,0) -> 40410 | W281: =IF(V281>5000,"Unpaid","Paid") -> Unpaid | X281: =VLOOKUP(B281,Food!A:B,2,0) -> Yes | Y281: =VLOOKUP(B281,'Call List'!A:A,1,0) -> A01259 | Z281: =VLOOKUP(B281,Sheet4!A:A,1,0) -> #N/A
A282: 281 | B282: A01253 | C282: KG II | D282: B | E282: SOUVIK ROUT | F282: SAUMYA RANJAN ROUT | G282: saumyarout1987@gmail.com | H282: 9853963652 | I282: SOUMYA SUCHARITA | J282: ssdrsony2@gmail.com | K282: 9861670992 | L282: 2022-2023 | M282: =VLOOKUP(B282,'HP List'!A:G,7,0) -> #N/A | N282: =VLOOKUP(B282,'HP List'!A:H,8,0) -> #N/A | P282: =VLOOKUP(B282,'Q1'!A:B,2,0) -> #N/A | Q282: =IF(P282>5000,"Unpaid","Paid") -> #N/A | R282: =VLOOKUP(B282,'Q2'!A:B,2,0) -> #N/A | S282: =IF(R282>5000,"Unpaid","Paid") -> #N/A | T282: =VLOOKUP(B282,'Q3'!A:B,2,0) -> #N/A | U282: =IF(T282>5000,"Unpaid","Paid") -> #N/A | V282: =VLOOKUP(B282,'Q4'!A:B,2,0) -> #N/A | W282: =IF(V282>5000,"Unpaid","Paid") -> #N/A | X282: =VLOOKUP(B282,Food!A:B,2,0) -> #N/A | Y282: =VLOOKUP(B282,'Call List'!A:A,1,0) -> A01253 | Z282: =VLOOKUP(B282,Sheet4!A:A,1,0) -> #N/A
A283: 282 | B283: A01299 | C283: KG II | D283: B | E283: Yash Bhawsinka | F283: Ankit Bhawsinka | G283: ankit_bhawsinka@live.in | H283: 9861430301 | I283: Meghna Bhawsinka | J283: meghnabhawsinka@gmail.com | K283: 9861869915 | L283: 2023-2024 | M283: =VLOOKUP(B283,'HP List'!A:G,7,0) -> #N/A | N283: =VLOOKUP(B283,'HP List'!A:H,8,0) -> #N/A | P283: =VLOOKUP(B283,'Q1'!A:B,2,0) -> #N/A | Q283: =IF(P283>5000,"Unpaid","Paid") -> #N/A | R283: =VLOOKUP(B283,'Q2'!A:B,2,0) -> #N/A | S283: =IF(R283>5000,"Unpaid","Paid") -> #N/A | T283: =VLOOKUP(B283,'Q3'!A:B,2,0) -> #N/A | U283: =IF(T283>5000,"Unpaid","Paid") -> #N/A | V283: =VLOOKUP(B283,'Q4'!A:B,2,0) -> 51360 | W283: =IF(V283>5000,"Unpaid","Paid") -> Unpaid | X283: =VLOOKUP(B283,Food!A:B,2,0) -> Yes | Y283: =VLOOKUP(B283,'Call List'!A:A,1,0) -> A01299 | Z283: =VLOOKUP(B283,Sheet4!A:A,1,0) -> #N/A
A284: 283 | B284: A01645 | C284: KG II | D284: C | E284: Aakriti Akankshya Sha | F284: Subhajyoti Sha | G284: subhayoti@gmail.com | H284: 9437549397 | I284: Ipsita Dash | J284: ipsitadash027@gmail.com | K284: 9437144822 | L284: 2025-2026 | M284: =VLOOKUP(B284,'HP List'!A:G,7,0) -> #N/A | N284: =VLOOKUP(B284,'HP List'!A:H,8,0) -> #N/A | P284: =VLOOKUP(B284,'Q1'!A:B,2,0) -> #N/A | Q284: =IF(P284>5000,"Unpaid","Paid") -> #N/A | R284: =VLOOKUP(B284,'Q2'!A:B,2,0) -> #N/A | S284: =IF(R284>5000,"Unpaid","Paid") -> #N/A | T284: =VLOOKUP(B284,'Q3'!A:B,2,0) -> #N/A | U284: =IF(T284>5000,"Unpaid","Paid") -> #N/A | V284: =VLOOKUP(B284,'Q4'!A:B,2,0) -> 47760 | W284: =IF(V284>5000,"Unpaid","Paid") -> Unpaid | X284: =VLOOKUP(B284,Food!A:B,2,0) -> #N/A | Y284: =VLOOKUP(B284,'Call List'!A:A,1,0) -> A01645 | Z284: =VLOOKUP(B284,Sheet4!A:A,1,0) -> #N/A
A285: 284 | B285: A01402 | C285: KG II | D285: C | E285: Advaya Kumar | F285: Sandeep Kumar | G285: sahur@indianoil.in | H285: 8587884899 | I285: Ritika Sahu | J285: sahur@indianoil.in | K285: 8587884899 | L285: 2023-2024 | M285: =VLOOKUP(B285,'HP List'!A:G,7,0) -> #N/A | N285: =VLOOKUP(B285,'HP List'!A:H,8,0) -> #N/A | P285: =VLOOKUP(B285,'Q1'!A:B,2,0) -> #N/A | Q285: =IF(P285>5000,"Unpaid","Paid") -> #N/A | R285: =VLOOKUP(B285,'Q2'!A:B,2,0) -> #N/A | S285: =IF(R285>5000,"Unpaid","Paid") -> #N/A | T285: =VLOOKUP(B285,'Q3'!A:B,2,0) -> #N/A | U285: =IF(T285>5000,"Unpaid","Paid") -> #N/A | V285: =VLOOKUP(B285,'Q4'!A:B,2,0) -> #N/A | W285: =IF(V285>5000,"Unpaid","Paid") -> #N/A | X285: =VLOOKUP(B285,Food!A:B,2,0) -> Yes | Y285: =VLOOKUP(B285,'Call List'!A:A,1,0) -> A01402 | Z285: =VLOOKUP(B285,Sheet4!A:A,1,0) -> #N/A
A286: 285 | B286: A01714 | C286: KG II | D286: C | E286: Advik Khandelwal | F286: Aman Khandelwal | G286: amankhandelwal91@gmail.com | H286: 9090776614 | I286: Shristi Khandelwal | J286: shristikhandelwal92@gmail.com | K286: 9572543642 | L286: 2025-2026 | M286: =VLOOKUP(B286,'HP List'!A:G,7,0) -> #N/A | N286: =VLOOKUP(B286,'HP List'!A:H,8,0) -> #N/A | P286: =VLOOKUP(B286,'Q1'!A:B,2,0) -> #N/A | Q286: =IF(P286>5000,"Unpaid","Paid") -> #N/A | R286: =VLOOKUP(B286,'Q2'!A:B,2,0) -> #N/A | S286: =IF(R286>5000,"Unpaid","Paid") -> #N/A | T286: =VLOOKUP(B286,'Q3'!A:B,2,0) -> #N/A | U286: =IF(T286>5000,"Unpaid","Paid") -> #N/A | V286: =VLOOKUP(B286,'Q4'!A:B,2,0) -> 40410 | W286: =IF(V286>5000,"Unpaid","Paid") -> Unpaid | X286: =VLOOKUP(B286,Food!A:B,2,0) -> Yes | Y286: =VLOOKUP(B286,'Call List'!A:A,1,0) -> A01714 | Z286: =VLOOKUP(B286,Sheet4!A:A,1,0) -> #N/A
A287: 286 | B287: A01792 | C287: KG II | D287: C | E287: Atharv Sharma | F287: Chandan Kumar | G287: k.chandan682@icloud.com | H287: 9689607620 | I287: Sapna Bharti | J287: sapnabharti36@gmail.com | K287: 9156612400 | L287: 2025-2026 | M287: =VLOOKUP(B287,'HP List'!A:G,7,0) -> #N/A | N287: =VLOOKUP(B287,'HP List'!A:H,8,0) -> #N/A | P287: =VLOOKUP(B287,'Q1'!A:B,2,0) -> #N/A | Q287: =IF(P287>5000,"Unpaid","Paid") -> #N/A | R287: =VLOOKUP(B287,'Q2'!A:B,2,0) -> #N/A | S287: =IF(R287>5000,"Unpaid","Paid") -> #N/A | T287: =VLOOKUP(B287,'Q3'!A:B,2,0) -> #N/A | U287: =IF(T287>5000,"Unpaid","Paid") -> #N/A | V287: =VLOOKUP(B287,'Q4'!A:B,2,0) -> 32403 | W287: =IF(V287>5000,"Unpaid","Paid") -> Unpaid | X287: =VLOOKUP(B287,Food!A:B,2,0) -> Yes | Y287: =VLOOKUP(B287,'Call List'!A:A,1,0) -> A01792 | Z287: =VLOOKUP(B287,Sheet4!A:A,1,0) -> #N/A
A288: 287 | B288: A01184 | C288: KG II | D288: C | E288: AWAAHAN MOHAPATRA | F288: AJAY KUMAR MOHAPATRA | G288: ajay.1515@gmail.com | H288: 9437032515 | I288: RASMITA KUMARI SAHU | J288: rasmita.mita@gmail.com | K288: 9439325568 | L288: 2022-2023 | M288: =VLOOKUP(B288,'HP List'!A:G,7,0) -> #N/A | N288: =VLOOKUP(B288,'HP List'!A:H,8,0) -> #N/A | P288: =VLOOKUP(B288,'Q1'!A:B,2,0) -> #N/A | Q288: =IF(P288>5000,"Unpaid","Paid") -> #N/A | R288: =VLOOKUP(B288,'Q2'!A:B,2,0) -> #N/A | S288: =IF(R288>5000,"Unpaid","Paid") -> #N/A | T288: =VLOOKUP(B288,'Q3'!A:B,2,0) -> #N/A | U288: =IF(T288>5000,"Unpaid","Paid") -> #N/A | V288: =VLOOKUP(B288,'Q4'!A:B,2,0) -> 52260 | W288: =IF(V288>5000,"Unpaid","Paid") -> Unpaid | X288: =VLOOKUP(B288,Food!A:B,2,0) -> Yes | Y288: =VLOOKUP(B288,'Call List'!A:A,1,0) -> A01184 | Z288: =VLOOKUP(B288,Sheet4!A:A,1,0) -> #N/A
A289: 288 | B289: A01545 | C289: KG II | D289: C | E289: Bhumanya Das | F289: Mrutyunjay Das | G289: dr.das.mrutyunjay@gmail.com | H289: 7978020842 | I289: Ipsa Priyadarshinee | J289: ipsasweet7@gmail.com | K289: 7008087227 | L289: 2024-2025 | M289: =VLOOKUP(B289,'HP List'!A:G,7,0) -> #N/A | N289: =VLOOKUP(B289,'HP List'!A:H,8,0) -> #N/A | P289: =VLOOKUP(B289,'Q1'!A:B,2,0) -> #N/A | Q289: =IF(P289>5000,"Unpaid","Paid") -> #N/A | R289: =VLOOKUP(B289,'Q2'!A:B,2,0) -> #N/A | S289: =IF(R289>5000,"Unpaid","Paid") -> #N/A | T289: =VLOOKUP(B289,'Q3'!A:B,2,0) -> #N/A | U289: =IF(T289>5000,"Unpaid","Paid") -> #N/A | V289: =VLOOKUP(B289,'Q4'!A:B,2,0) -> #N/A | W289: =IF(V289>5000,"Unpaid","Paid") -> #N/A | X289: =VLOOKUP(B289,Food!A:B,2,0) -> Yes | Y289: =VLOOKUP(B289,'Call List'!A:A,1,0) -> A01545 | Z289: =VLOOKUP(B289,Sheet4!A:A,1,0) -> #N/A
A290: 289 | B290: A01315 | C290: KG II | D290: C | E290: Jagvi Jaideep | F290: Jaideep Tripathy | G290: jaideeptripathy@gmail.com | H290: 8328840464 | I290: Samapika Nanda | J290: jaideeptripathy@gmail.com | K290: 9090908200 | L290: 2023-2024 | M290: =VLOOKUP(B290,'HP List'!A:G,7,0) -> #N/A | N290: =VLOOKUP(B290,'HP List'!A:H,8,0) -> #N/A | P290: =VLOOKUP(B290,'Q1'!A:B,2,0) -> 3000 | Q290: =IF(P290>5000,"Unpaid","Paid") -> Paid | R290: =VLOOKUP(B290,'Q2'!A:B,2,0) -> 3000 | S290: =IF(R290>5000,"Unpaid","Paid") -> Paid | T290: =VLOOKUP(B290,'Q3'!A:B,2,0) -> #N/A | U290: =IF(T290>5000,"Unpaid","Paid") -> #N/A | V290: =VLOOKUP(B290,'Q4'!A:B,2,0) -> 54060 | W290: =IF(V290>5000,"Unpaid","Paid") -> Unpaid | X290: =VLOOKUP(B290,Food!A:B,2,0) -> Yes | Y290: =VLOOKUP(B290,'Call List'!A:A,1,0) -> A01315 | Z290: =VLOOKUP(B290,Sheet4!A:A,1,0) -> #N/A
A291: 290 | B291: A01770 | C291: KG II | D291: C | E291: MARYAM FATIMA | F291: MOHAMMED MUHTASHIM RABBANI | G291: mm.rabbani@coalindia.in | H291: 8093075864 | I291: TARANNUM | J291: taanwar@microsoft.com | K291: 8008131323 | L291: 2025-2026 | M291: =VLOOKUP(B291,'HP List'!A:G,7,0) -> #N/A | N291: =VLOOKUP(B291,'HP List'!A:H,8,0) -> #N/A | P291: =VLOOKUP(B291,'Q1'!A:B,2,0) -> #N/A | Q291: =IF(P291>5000,"Unpaid","Paid") -> #N/A | R291: =VLOOKUP(B291,'Q2'!A:B,2,0) -> #N/A | S291: =IF(R291>5000,"Unpaid","Paid") -> #N/A | T291: =VLOOKUP(B291,'Q3'!A:B,2,0) -> #N/A | U291: =IF(T291>5000,"Unpaid","Paid") -> #N/A | V291: =VLOOKUP(B291,'Q4'!A:B,2,0) -> 32403 | W291: =IF(V291>5000,"Unpaid","Paid") -> Unpaid | X291: =VLOOKUP(B291,Food!A:B,2,0) -> #N/A | Y291: =VLOOKUP(B291,'Call List'!A:A,1,0) -> A01770 | Z291: =VLOOKUP(B291,Sheet4!A:A,1,0) -> #N/A
...

Sheet Call List
A1: Adm
A2: 15043
A3: 2250
A4: 15011
A5: 14945
A6: 14089
A7: 5863
A8: A01720
A9: 15083
A10: 15080
A11: 11252
A12: A01476
A13: 15046
A14: A01751
A15: A01763
A16: 15074
A17: 15072
A18: 14951
A19: 15049
A20: 11251
A21: 14875
A22: 15045
A23: 15086
A24: 14827
A25: 13435
A26: 14597
A27: 15079
... A34: 13466
A35: A01756
A36: A01802
A37: A01780
A38: A01606
A39: 14304
A40: A01796
A41: A01798
A42: 9933
A43: A01622
A44: 11918
A45: 12008
A46: 9120
...

Sheet Q1
A1: Adm | B1: Amount
A2: A01825 | B2: 2000
A3: A01632 | B3: 3000
A4: A01743 | B4: 1000
A5: A01774 | B5: 15
A6: A01778 | B6: 1000
A7: A01449 | B7: 3750
A8: A01357 | B8: 63050
A9: A01475 | B9: 20
A10: A01348 | B10: 11500
A11: A01662 | B11: 38110
A12: A01759 | B12: 1903
A13: A01800 | B13: 2500
... A18: A01264 | B18: 3500
A19: 14744 | B19: 7050
A20: 14468 | B20: 500
A21: 14964 | B21: 4000
A22: 15130 | B22: 7000
A23: 14971 | B23: 2200
A24: 14758 | B24: 4500
A25: 14379 | B25: 225870
A26: 14410 | B26: 2250
A27: 14953 | B27: 10000
A28: 13408 | B28: 500
A29: 14954 | B29: 9000
A30: 13663 | B30: 1500
... A287: 11660 | B287: 1000
B288: 3257143.7

Sheet Q2
A1: Adm | B1: Amount
A2: A01825 | B2: 2000
A3: A01632 | B3: 3000
A4: A01743 | B4: 1000
A5: A01774 | B5: 15
A6: A01778 | B6: 1000
A7: A01449 | B7: 3750
A8: A01357 | B8: 63050
A9: A01475 | B9: 20
A10: A01348 | B10: 11500
A11: A01662 | B11: 76220
A12: A01759 | B12: 1903
A13: A01800 | B13: 2500
... A19: A01264 | B19: 3500
A20: 14369 | B20: 2850
A21: 14744 | B21: 7050
A22: 14468 | B22: 500
A23: 14964 | B23: 4000
A24: 15130 | B24: 31915
A25: 14971 | B25: 2200
A26: 14758 | B26: 4500
A27: 14379 | B27: 289120
A28: 14348 | B28: 3200
A29: 14410 | B29: 2250
A30: 14953 | B30: 10000
A31: 13408 | B31: 500
... A456: 11660 | B456: 1000
B457: 5528042.2

Sheet Q3
A1: Adm | B1: Amount
A2: A01832 | B2: 4000
A3: A01825 | B3: 4700
A4: A01823 | B4: 5700
A5: A01456 | B5: 2850
A6: A01867 | B6: 69000
A7: A01851 | B7: 17655
A8: A01743 | B8: 1000
A9: A01774 | B9: 15
A10: A01814 | B10: 45878
A11: A01778 | B11: 1000
A12: A01449 | B12: 3750
A13: A01357 | B13: 63050
... A29: A01749 | B29: 36403
A30: 15022 | B30: 13750
A31: 14744 | B31: 7050
A32: 14468 | B32: 4000
A33: 14964 | B33: 35750
A34: 15130 | B34: 71537
A35: 14971 | B35: 2200
A36: 14758 | B36: 4500
A37: 14379 | B37: 352370
A38: 14410 | B38: 4250
A39: 14953 | B39: 10000
A40: 14343 | B40: 1000
A41: 13408 | B41: 4550
... A508: 11660 | B508: 1000
B509: 12243033

Sheet Q4
A1: Adm | B1: Amount
A2: 14386 | B2: 45600
A3: 14684 | B3: 54622
A4: 14347 | B4: 45600
A5: 14387 | B5: 45600
A6: 14441 | B6: 38550
A7: 14987 | B7: 9750
A8: 14373 | B8: 45600
A9: 14989 | B9: 9750
A10: 14740 | B10: 61500
A11: 14990 | B11: 9750
A12: 14988 | B12: 9750
A13: 14983 | B13: 43672
... A2715: 3944 | B2715: 140850
A2716: A01798 | B2716: 19950
A2717: A01836 | B2717: 17550
A2718: A01828 | B2718: 17550
A2719: A01692 | B2719: 17550
A2720: A01771 | B2720: 17550
A2721: A01827 | B2721: 17550
A2722: A01727 | B2722: 17550
A2723: A01820 | B2723: 23850
A2724: A01696 | B2724: 23850
A2725: A01652 | B2725: 14038
A2726: A01738 | B2726: 23850
A2727: A01805 | B2727: 17550
... A2950: A01723 | B2950: 54060

Sheet HP List
A1: Admission No. | B1: Student Name | C1: Class Name | D1: Section Name | E1: Father Name | F1: Mother Name | G1: HP List | H1: SMS | I1: Active_2526 | J1: Class Name | K1: Section Name | L1: Duplicate Check
A2: 2326 | B2: Saugat Satapathy | C2: =VLOOKUP(A2,'Student List'!B:C,2,0) -> XII Sci | D2: =VLOOKUP(A2,'Student List'!B:D,3,0) -> C | E2: Suranjan Satapathy | F2: Sunanda Hota | G2: HP | H2: Yes | I2: =VLOOKUP(A2,'Student List'!B:B,1,0) -> 2326 | J2: XI Sci | K2: H | L2: =COUNTIF(A:A,A2) -> 1
A3: 2402 | B3: Raiguru Suryansh Mohapatra | C3: =VLOOKUP(A3,'Student List'!B:C,2,0) -> XII Hum | D3: =VLOOKUP(A3,'Student List'!B:D,3,0) -> Q | E3: Rajguru Manas Kumar Mohapatra | F3: Debasmita Tripathy | G3: DND | H3: Yes_Awareness | I3: =VLOOKUP(A3,'Student List'!B:B,1,0) -> 2402 | J3: XI Hum | K3: Q | L3: =COUNTIF(A:A,A3) -> 1
A4: 3169 | B4: Nayantara Karthikeyan | C4: =VLOOKUP(A4,'Student List'!B:C,2,0) -> XI Sci | D4: =VLOOKUP(A4,'Student List'!B:D,3,0) -> C | E4: V. Karthikeya Pandian | F4: Sujata Karthikeyan | G4: DND | H4: No | I4: =VLOOKUP(A4,'Student List'!B:B,1,0) -> 3169 | J4: X | K4: B | L4: =COUNTIF(A:A,A4) -> 1
A5: 3990 | B5: Poorva Mishra | C5: =VLOOKUP(A5,'Student List'!B:C,2,0) -> XI Hum | D5: =VLOOKUP(A5,'Student List'!B:D,3,0) -> O | E5: Jyoti Prakash Mishra | F5: Smita Mahapatra | G5: HP | H5: Yes | I5: =VLOOKUP(A5,'Student List'!B:B,1,0) -> 3990 | J5: X | K5: B | L5: =COUNTIF(A:A,A5) -> 1
A6: 5036 | B6: Aryaman Mishra | C6: =VLOOKUP(A6,'Student List'!B:C,2,0) -> XI Sci | D6: =VLOOKUP(A6,'Student List'!B:D,3,0) -> I | E6: Priyadarshi Mishra | F6: Rosalin Patasani Mishra | G6: HP | H6: Yes | I6: =VLOOKUP(A6,'Student List'!B:B,1,0) -> 5036 | J6: X | K6: C | L6: =COUNTIF(A:A,A6) -> 1
A7: 6607 | B7: Nrupen Chakravarthy Ravella | C7: =VLOOKUP(A7,'Student List'!B:C,2,0) -> XII Sci | D7: =VLOOKUP(A7,'Student List'!B:D,3,0) -> F | E7: Vineel Krishna Ravella | F7: Srimula Venugopal Chandana | G7: DND | H7: Yes_Awareness | I7: =VLOOKUP(A7,'Student List'!B:B,1,0) -> 6607 | J7: XI Sci | K7: I | L7: =COUNTIF(A:A,A7) -> 1
A8: 7100 | B8: Yash Bidyadhar Mohapatra | C8: =VLOOKUP(A8,'Student List'!B:C,2,0) -> VIII | D8: =VLOOKUP(A8,'Student List'!B:D,3,0) -> A | E8: Lalitendu Bidyadhar Mohapatra | F8: Jogeshwari Devi | G8: HP | H8: Yes | I8: =VLOOKUP(A8,'Student List'!B:B,1,0) -> 7100 | J8: VII | K8: F | L8: =COUNTIF(A:A,A8) -> 1
A9: 8187 | B9: Amit Mahapatra | C9: =VLOOKUP(A9,'Student List'!B:C,2,0) -> VII | D9: =VLOOKUP(A9,'Student List'!B:D,3,0) -> C | E9: Sunil Kumar Mahapatra | F9: Shrutirekha Rayaguru | G9: DND | H9: No | I9: =VLOOKUP(A9,'Student List'!B:B,1,0) -> 8187 | J9: VI | K9: E | L9: =COUNTIF(A:A,A9) -> 1
A10: 8910 | B10: Kabir Chaudhary | C10: =VLOOKUP(A10,'Student List'!B:C,2,0) -> VIII | D10: =VLOOKUP(A10,'Student List'!B:D,3,0) -> A | E10: Prem Chandra Chaudhary | F10: Jyoti Verma | G10: HP | H10: Yes | I10: =VLOOKUP(A10,'Student List'!B:B,1,0) -> 8910 | J10: VII | K10: D | L10: =COUNTIF(A:A,A10) -> 1
A11: 9112 | B11: Priyansh Patnaik | C11: =VLOOKUP(A11,'Student List'!B:C,2,0) -> VIII | D11: =VLOOKUP(A11,'Student List'!B:D,3,0) -> F | E11: Radha Krishna Pattanaik | F11: Anamika Patnaik | G11: HP | H11: Yes | I11: =VLOOKUP(A11,'Student List'!B:B,1,0) -> 9112 | J11: VII | K11: J | L11: =COUNTIF(A:A,A11) -> 1
A12: 9121 | B12: Yatharth Singh | C12: =VLOOKUP(A12,'Student List'!B:C,2,0) -> #N/A | D12: =VLOOKUP(A12,'Student List'!B:D,3,0) -> #N/A | E12: Ashish Kumar Singh | F12: Babita Singh | G12: HP | H12: Yes | I12: =VLOOKUP(A12,'Student List'!B:B,1,0) -> #N/A | J12: X | K12: G | L12: =COUNTIF(A:A,A12) -> 1
A13: 9171 | B13: Harshita Das | C13: =VLOOKUP(A13,'Student List'!B:C,2,0) -> XII Sci | D13: =VLOOKUP(A13,'Student List'!B:D,3,0) -> H | E13: Avikesh Das | F13: Kumkum Das | G13: HP | H13: Yes | I13: =VLOOKUP(A13,'Student List'!B:B,1,0) -> 9171 | J13: XI Sci | K13: C | L13: =COUNTIF(A:A,A13) -> 1
... A82: 14361 | B82: Roma M | C82: =VLOOKUP(A82,'Student List'!B:C,2,0) -> I | D82: =VLOOKUP(A82,'Student List'!B:D,3,0) -> G | E82: Rajesh Kumar Mishra | F82: Pallavi Shahi | G82: HP | H82: Yes | I82: =VLOOKUP(A82,'Student List'!B:B,1,0) -> 14361 | J82: KG II | K82: B | L82: =COUNTIF(A:A,A82) -> 1
A83: A01594 | B83: Kadambari Singh Raghuvanshi | C83: =VLOOKUP(A83,'Student List'!B:C,2,0) -> #N/A | D83: =VLOOKUP(A83,'Student List'!B:D,3,0) -> #N/A | E83: Chintan Raghuvanshi | F83: Sanyogita Singh Chauhan | G83: HP | H83: Yes | I83: =VLOOKUP(A83,'Student List'!B:B,1,0) -> #N/A | J83: Play Group | K83: A | L83: =COUNTIF(A:A,A83) -> 1
A84: 14785 | B84: Abhirup Sahoo | C84: =VLOOKUP(A84,'Student List'!B:C,2,0) -> IV | D84: =VLOOKUP(A84,'Student List'!B:D,3,0) -> C | E84: Manoj Kumar Sahoo | F84: Bandita Sahoo | G84: HP | H84: Yes | I84: 14785 | J84: IV | K84: C | L84: =COUNTIF(A:A,A84) -> 1
A85: 14786 | B85: Adhiraaj Sahoo | C85: =VLOOKUP(A85,'Student List'!B:C,2,0) -> IX | D85: =VLOOKUP(A85,'Student List'!B:D,3,0) -> G | E85: Manoj Kumar Sahoo | F85: Bandita Sahoo | G85: HP | H85: Yes | I85: 14786 | J85: IX | K85: G | L85: =COUNTIF(A:A,A85) -> 1
A86: 14840 | B86: =VLOOKUP(A86,'Student List'!B:E,4,0) -> Pernita Mohanty | C86: =VLOOKUP(A86,'Student List'!B:C,2,0) -> IX | D86: =VLOOKUP(A86,'Student List'!B:D,3,0) -> G | E86: =VLOOKUP(A86,'Student List'!B:F,5,0) -> Prateek Mohanty | F86: =VLOOKUP(A86,'Student List'!B:I,8,0) -> Maitri Mohanty | G86: HP | H86: Yes | L86: =COUNTIF(A:A,A86) -> 1
A87: A01765 | B87: =VLOOKUP(A87,'Student List'!B:E,4,0) -> Devika Oram | C87: =VLOOKUP(A87,'Student List'!B:C,2,0) -> Nursery | D87: =VLOOKUP(A87,'Student List'!B:D,3,0) -> A | E87: =VLOOKUP(A87,'Student List'!B:F,5,0) -> Gurucharan Oram | F87: =VLOOKUP(A87,'Student List'!B:I,8,0) -> Eva Beck | G87: HP | H87: Yes | L87: =COUNTIF(A:A,A87) -> 1
A88: 14843 | B88: =VLOOKUP(A88,'Student List'!B:E,4,0) -> Devayani Oram | C88: =VLOOKUP(A88,'Student List'!B:C,2,0) -> I | D88: =VLOOKUP(A88,'Student List'!B:D,3,0) -> D | E88: =VLOOKUP(A88,'Student List'!B:F,5,0) -> Gurucharan Oram | F88: =VLOOKUP(A88,'Student List'!B:I,8,0) -> Eva Beck | G88: HP | H88: Yes | L88: =COUNTIF(A:A,A88) -> 1
A89: 14841 | B89: =VLOOKUP(A89,'Student List'!B:E,4,0) -> Ashok Oram | C89: =VLOOKUP(A89,'Student List'!B:C,2,0) -> V | D89: =VLOOKUP(A89,'Student List'!B:D,3,0) -> H | E89: =VLOOKUP(A89,'Student List'!B:F,5,0) -> Fulchand Oram | F89: =VLOOKUP(A89,'Student List'!B:I,8,0) -> Sanjita Oram | G89: HP | H89: Yes | L89: =COUNTIF(A:A,A89) -> 1
A90: 14842 | B90: =VLOOKUP(A90,'Student List'!B:E,4,0) -> Harsbardhan Oram | C90: =VLOOKUP(A90,'Student List'!B:C,2,0) -> III | D90: =VLOOKUP(A90,'Student List'!B:D,3,0) -> E | E90: =VLOOKUP(A90,'Student List'!B:F,5,0) -> Fulchand Oram | F90: =VLOOKUP(A90,'Student List'!B:I,8,0) -> Sanjita Oram | G90: HP | H90: Yes | L90: =COUNTIF(A:A,A90) -> 1
A91: 14844 | B91: =VLOOKUP(A91,'Student List'!B:E,4,0) -> Sidharth Oram | C91: =VLOOKUP(A91,'Student List'!B:C,2,0) -> VIII | D91: =VLOOKUP(A91,'Student List'!B:D,3,0) -> C | E91: =VLOOKUP(A91,'Student List'!B:F,5,0) -> Fulchand Oram | F91: =VLOOKUP(A91,'Student List'!B:I,8,0) -> Sanjita Oram | G91: HP | H91: Yes | L91: =COUNTIF(A:A,A91) -> 1
A92: A01764 | B92: =VLOOKUP(A92,'Student List'!B:E,4,0) -> Atharva Mishra | C92: =VLOOKUP(A92,'Student List'!B:C,2,0) -> KG II | D92: =VLOOKUP(A92,'Student List'!B:D,3,0) -> E | E92: =VLOOKUP(A92,'Student List'!B:F,5,0) -> Pinak Mishra | F92: =VLOOKUP(A92,'Student List'!B:I,8,0) -> Lara Mishra | G92: HP | H92: Yes | L92: =COUNTIF(A:A,A92) -> 1
A93: 14858 | B93: =VLOOKUP(A93,'Student List'!B:E,4,0) -> Swastik Mahapatra | C93: =VLOOKUP(A93,'Student List'!B:C,2,0) -> IX | D93: =VLOOKUP(A93,'Student List'!B:D,3,0) -> I | E93: =VLOOKUP(A93,'Student List'!B:F,5,0) -> Krushna Chandra Mahapatra | F93: =VLOOKUP(A93,'Student List'!B:I,8,0) -> Anuradha Debatta | G93: HP | H93: Yes | L93: =COUNTIF(A:A,A93) -> 1
A94: 14857 | B94: =VLOOKUP(A94,'Student List'!B:E,4,0) -> Govind Nair | C94: =VLOOKUP(A94,'Student List'!B:C,2,0) -> VIII | D94: =VLOOKUP(A94,'Student List'!B:D,3,0) -> B | E94: =VLOOKUP(A94,'Student List'!B:F,5,0) -> Manoj V Nair | F94: =VLOOKUP(A94,'Student List'!B:I,8,0) -> Aswathy S | G94: HP | H94: Yes | L94: =COUNTIF(A:A,A94) -> 1
A95: A01687 | B95: =VLOOKUP(A95,'Student List'!B:E,4,0) -> Sharun Mishra | C95: =VLOOKUP(A95,'Student List'!B:C,2,0) -> Nursery | D95: =VLOOKUP(A95,'Student List'!B:D,3,0) -> B | E95: =VLOOKUP(A95,'Student List'!B:F,5,0) -> Shivendra Kumar Mishra | F95: =VLOOKUP(A95,'Student List'!B:I,8,0) -> Ami Choubey | G95: HP | H95: Yes | L95: =COUNTIF(A:A,A95) -> 1
A96: A01688 | B96: =VLOOKUP(A96,'Student List'!B:E,4,0) -> Shaurya Mishra | C96: =VLOOKUP(A96,'Student List'!B:C,2,0) -> Nursery | D96: =VLOOKUP(A96,'Student List'!B:D,3,0) -> B | E96: =VLOOKUP(A96,'Student List'!B:F,5,0) -> Shivendra Kumar Mishra | F96: =VLOOKUP(A96,'Student List'!B:I,8,0) -> Ami Choubey | G96: HP | H96: Yes | L96: =COUNTIF(A:A,A96) -> 1
A97: 14993 | B97: =VLOOKUP(A97,'Student List'!B:E,4,0) -> Shreyansh Nayak | C97: =VLOOKUP(A97,'Student List'!B:C,2,0) -> XI Com | D97: =VLOOKUP(A97,'Student List'!B:D,3,0) -> M | E97: =VLOOKUP(A97,'Student List'!B:F,5,0) -> Mahendra Nayak | F97: =VLOOKUP(A97,'Student List'!B:I,8,0) -> Sindhu Nandini Nayak | G97: HP_NPS | H97: Yes | L97: =COUNTIF(A:A,A98) -> 1
